<robot name = "robot">
    <link name="torso0">
        <inertial>
            <origin xyz="0 0 1.2431831953353694" rpy="0 0 0"/>
            <mass value="1" />
            <inertia ixx="100" ixy="0" ixz="0" iyy="100" iyz="0" izz="100" />
        </inertial>
        <visual>
            <origin xyz="0 0 1.2431831953353694" rpy="0 0 0"/>
            <geometry>
                <box size="0.5102758794825688 0.6107817401114244 0.5082873115911231" />
            </geometry>
            <material name="Cyan">
                <color rgba="0 1 1 1"/>
            </material>
        </visual>
        <collision>
            <origin xyz="0 0 1.2431831953353694" rpy="0 0 0"/>
            <geometry>
                <box size="0.5102758794825688 0.6107817401114244 0.5082873115911231" />
            </geometry>
        </collision>
    </link>
    <joint name="torso0_torso1" type="revolute">
       <parent link="torso0"/>
       <child  link="torso1"/>
       <origin rpy="0 0 0" xyz="0.0 0.3053908700557122 1.4973268511309308" />
       <axis xyz="0 1 0"/>
       <limit effort="0.0" lower="-3.14159" upper="3.14159" velocity="0.0"/>
    </joint>
    <link name="torso1">
        <inertial>
            <origin xyz="0.0 0.39710314492168564 0.37267414486422334" rpy="0 0 0"/>
            <mass value="1" />
            <inertia ixx="100" ixy="0" ixz="0" iyy="100" iyz="0" izz="100" />
        </inertial>
        <visual>
            <origin xyz="0.0 0.39710314492168564 0.37267414486422334" rpy="0 0 0"/>
            <geometry>
                <box size="0.6953009824548138 0.7942062898433713 0.7453482897284467" />
            </geometry>
            <material name="Green">
                <color rgba="0 1 0 1"/>
            </material>
        </visual>
        <collision>
            <origin xyz="0.0 0.39710314492168564 0.37267414486422334" rpy="0 0 0"/>
            <geometry>
                <box size="0.6953009824548138 0.7942062898433713 0.7453482897284467" />
            </geometry>
        </collision>
    </link>
    <joint name="torso0_torso2" type="revolute">
       <parent link="torso0"/>
       <child  link="torso2"/>
       <origin rpy="0 0 0" xyz="0.2551379397412844 0.3053908700557122 0.9890395395398078" />
       <axis xyz="0 1 0"/>
       <limit effort="0.0" lower="-3.14159" upper="3.14159" velocity="0.0"/>
    </joint>
    <link name="torso2">
        <inertial>
            <origin xyz="0.4743594274708297 0.42568269040822326 -0.49451976976990397" rpy="0 0 0"/>
            <mass value="1" />
            <inertia ixx="100" ixy="0" ixz="0" iyy="100" iyz="0" izz="100" />
        </inertial>
        <visual>
            <origin xyz="0.4743594274708297 0.42568269040822326 -0.49451976976990397" rpy="0 0 0"/>
            <geometry>
                <box size="0.9487188549416594 0.8513653808164465 0.9890395395398079" />
            </geometry>
            <material name="Green">
                <color rgba="0 1 0 1"/>
            </material>
        </visual>
        <collision>
            <origin xyz="0.4743594274708297 0.42568269040822326 -0.49451976976990397" rpy="0 0 0"/>
            <geometry>
                <box size="0.9487188549416594 0.8513653808164465 0.9890395395398079" />
            </geometry>
        </collision>
    </link>
</robot>