<robot name = "robot">
    <link name="torso0">
        <inertial>
            <origin xyz="0 0 0.47469156902367443" rpy="0 0 0"/>
            <mass value="1" />
            <inertia ixx="100" ixy="0" ixz="0" iyy="100" iyz="0" izz="100" />
        </inertial>
        <visual>
            <origin xyz="0 0 0.47469156902367443" rpy="0 0 0"/>
            <geometry>
                <box size="0.7402846252169596 0.7935535112319546 0.9493831380473489" />
            </geometry>
            <material name="Green">
                <color rgba="0 1 0 1"/>
            </material>
        </visual>
        <collision>
            <origin xyz="0 0 0.47469156902367443" rpy="0 0 0"/>
            <geometry>
                <box size="0.7402846252169596 0.7935535112319546 0.9493831380473489" />
            </geometry>
        </collision>
    </link>
    <joint name="torso0_torso1" type="revolute">
       <parent link="torso0"/>
       <child  link="torso1"/>
       <origin rpy="0 0 0" xyz="-0.3701423126084798 -0.3967767556159773 0.9493831380473489" />
       <axis xyz="0 1 0"/>
       <limit effort="0.0" lower="-3.14159" upper="3.14159" velocity="0.0"/>
    </joint>
    <link name="torso1">
        <inertial>
            <origin xyz="-0.25128272690843434 -0.3931889398443991 0.2599912096568414" rpy="0 0 0"/>
            <mass value="1" />
            <inertia ixx="100" ixy="0" ixz="0" iyy="100" iyz="0" izz="100" />
        </inertial>
        <visual>
            <origin xyz="-0.25128272690843434 -0.3931889398443991 0.2599912096568414" rpy="0 0 0"/>
            <geometry>
                <box size="0.5025654538168687 0.7863778796887982 0.5199824193136828" />
            </geometry>
            <material name="Green">
                <color rgba="0 1 0 1"/>
            </material>
        </visual>
        <collision>
            <origin xyz="-0.25128272690843434 -0.3931889398443991 0.2599912096568414" rpy="0 0 0"/>
            <geometry>
                <box size="0.5025654538168687 0.7863778796887982 0.5199824193136828" />
            </geometry>
        </collision>
    </link>
</robot>