<robot name = "robot">
    <link name="link0">
        <inertial>
            <origin xyz="0 0 0.5" rpy="0 0 0"/>
            <mass value="1" />
            <inertia ixx="100" ixy="0" ixz="0" iyy="100" iyz="0" izz="100" />
        </inertial>
        <visual>
            <origin xyz="0 0 0.5" rpy="0 0 0"/>
            <geometry>
                <box size="0.8450099203277692 0.4030195561385245 0.8198738861892394" />
            </geometry>
            <material name="Cyan">
                <color rgba="0 1 1 1"/>
            </material>
        </visual>
        <collision>
            <origin xyz="0 0 0.5" rpy="0 0 0"/>
            <geometry>
                <box size="0.8450099203277692 0.4030195561385245 0.8198738861892394" />
            </geometry>
        </collision>
    </link>
    <joint name="link0_link1" type="revolute">
       <parent link="link0"/>
       <child  link="link1"/>
       <origin rpy="0 0 0" xyz="0.4225049601638846 0 0.5" />
       <axis xyz="0 1 0"/>
       <limit effort="0.0" lower="-3.14159" upper="3.14159" velocity="0.0"/>
    </joint>
    <link name="link1">
        <inertial>
            <origin xyz="0.41745297443806284 0 0" rpy="0 0 0"/>
            <mass value="1" />
            <inertia ixx="100" ixy="0" ixz="0" iyy="100" iyz="0" izz="100" />
        </inertial>
        <visual>
            <origin xyz="0.41745297443806284 0 0" rpy="0 0 0"/>
            <geometry>
                <box size="0.8349059488761257 0.8043280033889657 0.33450467746856416" />
            </geometry>
            <material name="Green">
                <color rgba="0 1 0 1"/>
            </material>
        </visual>
        <collision>
            <origin xyz="0.41745297443806284 0 0" rpy="0 0 0"/>
            <geometry>
                <box size="0.8349059488761257 0.8043280033889657 0.33450467746856416" />
            </geometry>
        </collision>
    </link>
    <joint name="link1_link2" type="revolute">
       <parent link="link1"/>
       <child  link="link2"/>
       <origin rpy="0 0 0" xyz="0.8349059488761257 0 0" />
       <axis xyz="0 1 0"/>
       <limit effort="0.0" lower="-3.14159" upper="3.14159" velocity="0.0"/>
    </joint>
    <link name="link2">
        <inertial>
            <origin xyz="0.2953734700445589 0 0" rpy="0 0 0"/>
            <mass value="1" />
            <inertia ixx="100" ixy="0" ixz="0" iyy="100" iyz="0" izz="100" />
        </inertial>
        <visual>
            <origin xyz="0.2953734700445589 0 0" rpy="0 0 0"/>
            <geometry>
                <box size="0.5907469400891178 0.694286694201677 0.6377173949275491" />
            </geometry>
            <material name="Green">
                <color rgba="0 1 0 1"/>
            </material>
        </visual>
        <collision>
            <origin xyz="0.2953734700445589 0 0" rpy="0 0 0"/>
            <geometry>
                <box size="0.5907469400891178 0.694286694201677 0.6377173949275491" />
            </geometry>
        </collision>
    </link>
</robot>