<robot name = "robot">
    <link name="link0">
        <inertial>
            <origin xyz="0 0 0.5" rpy="0 0 0"/>
            <mass value="1" />
            <inertia ixx="100" ixy="0" ixz="0" iyy="100" iyz="0" izz="100" />
        </inertial>
        <visual>
            <origin xyz="0 0 0.5" rpy="0 0 0"/>
            <geometry>
                <box size="0.5241860896300164 0.3149064069468921 0.5527679749422072" />
            </geometry>
            <material name="Green">
                <color rgba="0 1 0 1"/>
            </material>
        </visual>
        <collision>
            <origin xyz="0 0 0.5" rpy="0 0 0"/>
            <geometry>
                <box size="0.5241860896300164 0.3149064069468921 0.5527679749422072" />
            </geometry>
        </collision>
    </link>
    <joint name="link0_link1" type="revolute">
       <parent link="link0"/>
       <child  link="link1"/>
       <origin rpy="0 0 0" xyz="0.2620930448150082 0 0.5" />
       <axis xyz="0 1 0"/>
       <limit effort="0.0" lower="-3.14159" upper="3.14159" velocity="0.0"/>
    </joint>
    <link name="link1">
        <inertial>
            <origin xyz="0.4383702834057015 0 0" rpy="0 0 0"/>
            <mass value="1" />
            <inertia ixx="100" ixy="0" ixz="0" iyy="100" iyz="0" izz="100" />
        </inertial>
        <visual>
            <origin xyz="0.4383702834057015 0 0" rpy="0 0 0"/>
            <geometry>
                <box size="0.876740566811403 0.7744892190915794 0.39892339540008576" />
            </geometry>
            <material name="Cyan">
                <color rgba="0 1 1 1"/>
            </material>
        </visual>
        <collision>
            <origin xyz="0.4383702834057015 0 0" rpy="0 0 0"/>
            <geometry>
                <box size="0.876740566811403 0.7744892190915794 0.39892339540008576" />
            </geometry>
        </collision>
    </link>
    <joint name="link1_link2" type="revolute">
       <parent link="link1"/>
       <child  link="link2"/>
       <origin rpy="0 0 0" xyz="0.876740566811403 0 0" />
       <axis xyz="0 1 0"/>
       <limit effort="0.0" lower="-3.14159" upper="3.14159" velocity="0.0"/>
    </joint>
    <link name="link2">
        <inertial>
            <origin xyz="0.27786995985343677 0 0" rpy="0 0 0"/>
            <mass value="1" />
            <inertia ixx="100" ixy="0" ixz="0" iyy="100" iyz="0" izz="100" />
        </inertial>
        <visual>
            <origin xyz="0.27786995985343677 0 0" rpy="0 0 0"/>
            <geometry>
                <box size="0.5557399197068735 0.6245772676999037 0.7405974349245488" />
            </geometry>
            <material name="Green">
                <color rgba="0 1 0 1"/>
            </material>
        </visual>
        <collision>
            <origin xyz="0.27786995985343677 0 0" rpy="0 0 0"/>
            <geometry>
                <box size="0.5557399197068735 0.6245772676999037 0.7405974349245488" />
            </geometry>
        </collision>
    </link>
    <joint name="link2_link3" type="revolute">
       <parent link="link2"/>
       <child  link="link3"/>
       <origin rpy="0 0 0" xyz="0.5557399197068735 0 0" />
       <axis xyz="0 1 0"/>
       <limit effort="0.0" lower="-3.14159" upper="3.14159" velocity="0.0"/>
    </joint>
    <link name="link3">
        <inertial>
            <origin xyz="0.2961694932104205 0 0" rpy="0 0 0"/>
            <mass value="1" />
            <inertia ixx="100" ixy="0" ixz="0" iyy="100" iyz="0" izz="100" />
        </inertial>
        <visual>
            <origin xyz="0.2961694932104205 0 0" rpy="0 0 0"/>
            <geometry>
                <box size="0.592338986420841 0.7843453401340477 0.33081950618534833" />
            </geometry>
            <material name="Cyan">
                <color rgba="0 1 1 1"/>
            </material>
        </visual>
        <collision>
            <origin xyz="0.2961694932104205 0 0" rpy="0 0 0"/>
            <geometry>
                <box size="0.592338986420841 0.7843453401340477 0.33081950618534833" />
            </geometry>
        </collision>
    </link>
</robot>